File: S2DataExample.txt
[Data]
Comment,Time Stamp (sec),Status (code),Temperature (K),Magnetic Field (Oe),Sample Position (degrees),Bridge 1 Resistivity (Ohm-m),Bridge 1 Excitation (uA),Bridge 2 Resistivity (Ohm-m),Bridge 2 Excitation (uA),Bridge 3 Resistivity (Ohm-m),Bridge 3 Excitation (uA),Bridge 4 Resistivity (Ohm-m),Bridge 4 Excitation (uA),Bridge 1 Std. Dev. (Ohm-m),Bridge 2 Std. Dev. (Ohm-m),Bridge 3 Std. Dev. (Ohm-m),Bridge 4 Std. Dev. (Ohm-m),Number of Readings,Bridge 1 Resistance (Ohms),Bridge 2 Resistance (Ohms),Bridge 3 Resistance (Ohms),Bridge 4 Resistance (Ohms)
,24067010.949,,2.00027380466461,-89318.94,0,-3.21840778924525e-006,999.890258789063,9.802505671978e-006,999.890258789063,9.73401764035225e-005,956.139587402344,,,7.65870176307175e-008,6.27555820887121e-008,6.26231108420449e-007,,25,-0.00321840778924525,0.009802505671978,0.0973401764035225,
,24067029.498,,1.99992875576019,-87850.889375,0,-3.4963765181601e-006,999.890258789063,9.79645971208811e-006,999.890258789063,9.76413169503212e-005,956.139587402344,,,7.42894638645281e-008,6.9114070711106e-008,8.68526470035203e-007,,25,-0.0034963765181601,0.00979645971208811,0.0976413169503212,
,24067048.171,,1.99995108127594,-86351.144375,0,-3.74088073149323e-006,999.890258789063,9.82645347714424e-006,999.890258789063,9.75332909822464e-005,956.139587402344,,,6.77715358059824e-008,6.58326782618396e-008,4.96495353883611e-007,,25,-0.00374088073149323,0.00982645347714424,0.0975332909822464,
,24067067.188,,1.99998684406281,-84853.74625,0,-3.93316651694477e-006,999.890258789063,9.91605557501316e-006,999.890258789063,9.75294280052185e-005,956.139587402344,,,3.30014557491331e-007,2.65995311704485e-007,5.10351389317294e-007,,25,-0.00393316651694477,0.00991605557501316,0.0975294280052185,
,24067086.142,,1.99997775554657,-83362.8475,0,-3.78182792337611e-006,999.890258789063,9.91930563002825e-006,999.890258789063,9.73301282525063e-005,956.139587402344,,,7.07346847563074e-007,1.97210081007656e-007,4.92373129724219e-007,,25,-0.00378182792337611,0.00991930563002825,0.0973301282525063,
,24067104.581,,2.00000510692596,-81873.411875,0,-3.62136615440249e-006,999.890258789063,9.87588468939066e-006,999.890258789063,9.75869873166084e-005,956.139587402344,,,7.26045829255942e-008,5.4543279981759e-008,5.21535826579267e-007,,25,-0.00362136615440249,0.00987588468939066,0.0975869873166084,
,24067123.941,,2.00005013942719,-80361.8609375,0,-3.37276833131909e-006,999.890258789063,9.90097895264626e-006,999.890258789063,9.72936850786209e-005,956.139587402344,,,7.34906039072446e-008,6.67169914071079e-008,7.37416766335468e-007,,25,-0.00337276833131909,0.00990097895264625,0.0972936850786209,
,24067142.645,,2.00005858421326,-78877.864375,0,-3.16712603904307e-006,999.890258789063,9.8979202285409e-006,999.890258789063,9.74210488796234e-005,956.139587402344,,,4.88004747153109e-008,6.74958442292977e-008,5.95635990599621e-007,,25,-0.00316712603904307,0.0098979202285409,0.0974210488796234,
,24067161.1,,1.99999707698822,-77397.846875,0,-3.07508370839059e-006,999.890258789063,9.91812795400619e-006,999.890258789063,9.75221738219261e-005,956.139587402344,,,2.39280207452801e-008,5.94024998486895e-008,9.58084347501849e-007,,25,-0.00307508370839059,0.0099181279540062,0.0975221738219261,
,24067180.366,,2.0000452041626,-75856.143125,0,-3.09142688289285e-006,999.890258789063,9.9337900057435e-006,999.890258789063,9.72463235259056e-005,956.139587402344,,,3.55807778938317e-008,6.05793640786924e-008,5.61889410702122e-007,,25,-0.00309142688289285,0.0099337900057435,0.0972463235259056,
,24067199.445,,2.00006462097168,-74366.69625,0,-3.17629551514983e-006,999.890258789063,9.93818696588278e-006,999.890258789063,9.71650162339211e-005,956.139587402344,,,1.2405557972228e-007,8.3747373558054e-008,5.48160311074071e-007,,25,-0.00317629551514983,0.00993818696588278,0.0971650162339211,
,24067217.916,,1.99999837875366,-72886.934375,0,-3.39437190443277e-006,999.890258789063,9.96716130524874e-006,999.890258789063,9.7225670516491e-005,956.139587402344,,,5.17912933759344e-008,7.42146832726089e-008,4.31189730307851e-007,,25,-0.00339437190443277,0.00996716130524874,0.0972256705164909,
,24067236.808,,1.99995661258698,-71374.9278125,0,-3.57601589523256e-006,999.890258789063,1.0094779767096e-005,999.890258789063,9.70481672883034e-005,956.139587402344,,,4.54928642826451e-007,3.38559837466766e-007,5.89135360903358e-007,,25,-0.00357601589523256,0.010094779767096,0.0970481672883034,
,24067255.871,,1.99997619628906,-69896.694375,0,-3.61683113500476e-006,999.890258789063,9.93145916610956e-006,999.890258789063,9.73751363158226e-005,956.139587402344,,,2.4029996208462e-007,2.81291489162978e-007,4.06599194931728e-007,,25,-0.00361683113500476,0.00993145916610956,0.0973751363158226,
,24067274.154,,2.00006966114044,-68433.4175,0,-3.51576295681298e-006,999.890258789063,1.00146786868572e-005,999.890258789063,9.71668010950089e-005,956.139587402344,,,4.48601925123279e-008,6.66407640553714e-008,5.41324277904128e-007,,25,-0.00351576295681298,0.0100146786868572,0.0971668010950088,
,24067293.062,,1.99996483802795,-66933.0690625,0,-3.36287304759026e-006,999.890258789063,1.00555207207799e-005,999.890258789063,9.72184696793556e-005,956.139587402344,,,5.48101989973023e-008,1.11840270620294e-007,6.16844405253441e-007,,25,-0.00336287304759026,0.0100555207207799,0.0972184696793556,
,24068300.937,,2.0001231098175,-89256.0734375,0,-3.77560223452747e-006,999.890258789063,5.65859995782375e-006,959.914653744698,-2.1940850019455e-005,959.914653744698,,,8.49971158514801e-008,2.00863242616318e-005,0.000586313154679526,,25,-0.00377560223452747,0.00565859995782375,-0.021940850019455,
,24068337.036,,2.00027505874634,-89319.4428125,0,-3.74587503261864e-006,999.890258789063,9.70192898064852e-006,999.890258789063,9.77842158079147e-005,999.890258789063,,,7.02785908990081e-008,6.96180132498202e-008,7.65269385097838e-007,,25,-0.00374587503261864,0.00970192898064852,0.0977842158079147,
,24068355.678,,2.00001053333282,-87805.105,0,-4.0391316358e-006,999.890258789063,9.73608899861574e-006,999.890258789063,9.76393181085587e-005,999.890258789063,,,9.20237415475916e-008,6.78217576544651e-008,5.52733539461353e-007,,25,-0.0040391316358,0.00973608899861574,0.0976393181085587,
,24068375.038,,2.00002357959747,-86297.451875,0,-4.33051694184542e-006,999.890258789063,9.77809678763151e-006,999.890258789063,9.7620390355587e-005,999.890258789063,,,7.06644593803315e-008,6.49949042133995e-008,6.9606320740782e-007,,25,-0.00433051694184542,0.00977809678763151,0.097620390355587,
,24068393.555,,1.99998722553253,-84832.4590625,0,-4.46322804316878e-006,999.890258789063,9.76862151175738e-006,999.890258789063,9.76549211144447e-005,999.890258789063,,,3.64533406500422e-008,6.36228823554163e-008,6.18830621726964e-007,,25,-0.00446322804316878,0.00976862151175737,0.0976549211144447,
,24068412.01,,1.99997685432434,-83346.9275,0,-4.39638871699572e-006,999.890258789063,9.77928914129734e-006,999.890258789063,9.75962689518929e-005,999.890258789063,,,7.00520233482524e-008,8.76568294024155e-008,8.19799501316754e-007,,25,-0.00439638871699572,0.00977928914129734,0.0975962689518929,
,24068431.307,,2.00002924442291,-81843.21375,0,-4.15848240256309e-006,999.890258789063,9.7829956561327e-006,999.890258789063,9.75712180137634e-005,999.890258789063,,,8.47282861066919e-008,6.06784831953472e-008,6.98917351882634e-007,,25,-0.0041584824025631,0.0097829956561327,0.0975712180137634,
,24068449.684,,1.99998225212097,-80377.6925,0,-3.88296760618687e-006,999.890258789063,9.81927040964365e-006,999.890258789063,9.74880349636078e-005,999.890258789063,,,8.77264316246733e-008,6.16824688777361e-008,8.19498853818453e-007,,25,-0.00388296760618687,0.00981927040964365,0.0974880349636078,
,24068468.124,,1.99995990276337,-78910.859375,0,-3.65081693977118e-006,999.890258789063,9.84350156038999e-006,999.890258789063,9.75165203213692e-005,999.890258789063,,,6.3725710611579e-008,5.93287856777518e-008,6.80321190765704e-007,,25,-0.00365081693977118,0.00984350156039,0.0975165203213692,
,24068487.062,,1.99995870113373,-77378.42625,0,-3.54569658637047e-006,999.890258789063,9.82988778501749e-006,999.890258789063,9.7530737221241e-005,999.890258789063,,,3.810718528869e-008,5.54941939846143e-008,7.27329289638619e-007,,25,-0.00354569658637047,0.00982988778501749,0.097530737221241,
,24068506.578,,1.99994555950165,-75871.06875,0,-3.58316647820175e-006,999.890258789063,9.84733819961548e-006,999.890258789063,9.74199521541596e-005,999.890258789063,,,4.53951976021042e-008,5.38345213001566e-008,6.08125090960229e-007,,25,-0.00358316647820175,0.00984733819961548,0.0974199521541596,
,24068525.235,,1.99997583866119,-74390.238125,0,-3.74400265514851e-006,999.890258789063,9.86258435994387e-006,999.890258789063,9.77944120764732e-005,999.890258789063,,,6.45086747006906e-008,7.02401457696215e-008,7.31176243031114e-007,,25,-0.00374400265514851,0.00986258435994387,0.0977944120764732,
,24068543.831,,1.99995309829712,-72886.9146875,0,-3.93362073227763e-006,999.890258789063,9.88605696707964e-006,999.890258789063,9.73609030246735e-005,999.890258789063,,,6.55016302945366e-008,5.24625686857061e-008,7.84397113540748e-007,,25,-0.00393362073227763,0.00988605696707964,0.0973609030246735,
,24068562.801,,2.00002408981323,-71410.4525,0,-4.09746574237943e-006,999.890258789063,9.89186555147171e-006,999.890258789063,9.74635660648346e-005,999.890258789063,,,5.95297062465195e-008,4.66214596427304e-008,7.60326818403118e-007,,25,-0.00409746574237943,0.00989186555147171,0.0974635660648346,
,24068581.443,,2.00001863956451,-69927.5034375,0,-4.13779085502028e-006,999.890258789063,9.90473415702582e-006,999.890258789063,9.71164551377296e-005,999.890258789063,,,4.11408260975791e-008,4.50881319477147e-008,6.30245766073075e-007,,25,-0.00413779085502028,0.00990473415702581,0.0971164551377297,
,24068600.085,,2.00002801418304,-68419.73625,0,-4.03632585890591e-006,999.890258789063,9.92396730929613e-006,999.890258789063,9.72897759079933e-005,999.890258789063,,,7.17796350497284e-008,4.50754412609874e-008,7.53618094223792e-007,,25,-0.00403632585890591,0.00992396730929613,0.0972897759079933,
,24068619.257,,1.99997318744659,-66921.653125,0,-3.84879008866846e-006,999.890258789063,9.93373285979032e-006,999.890258789063,9.71299982070923e-005,999.890258789063,,,5.91890298077601e-008,4.62225397989036e-008,7.40795938830239e-007,,25,-0.00384879008866847,0.00993373285979032,0.0971299982070923,
,24068638.055,,1.99998495578766,-65435.516875,0,-3.69427449069917e-006,999.890258789063,9.97688967734575e-006,999.890258789063,9.72663286328316e-005,999.890258789063,,,3.58653343248718e-008,4.4891542112304e-008,6.04678620325039e-007,,25,-0.00369427449069917,0.00997688967734575,0.0972663286328316,
,24068656.557,,1.999992852211,-63960.0096875,0,-3.67748786695302e-006,999.890258789063,1.0000711530447e-005,999.890258789063,9.7082956135273e-005,999.890258789063,,,4.77063035073769e-008,4.92278655609244e-008,6.76212277792712e-007,,25,-0.00367748786695302,0.010000711530447,0.097082956135273,
,24068675.808,,1.99995031833649,-62426.77375,0,-3.80437317304313e-006,999.890258789063,1.00399304926395e-005,999.890258789063,9.71144962310791e-005,999.890258789063,,,6.92793566570595e-008,5.64896376766801e-008,8.80955930743659e-007,,25,-0.00380437317304313,0.0100399304926395,0.0971144962310791,
,24068694.372,,2.00005927562714,-60966.2746875,0,-3.96067980676889e-006,999.890258789063,1.00376003980637e-005,999.890258789063,9.71934497356415e-005,999.890258789063,,,7.66734468492474e-008,5.80842502397633e-008,7.23840737025658e-007,,25,-0.00396067980676889,0.0100376003980637,0.0971934497356415,
,24068712.858,,2.00002117156982,-59485.1071875,0,-4.04106082394719e-006,999.890258789063,1.00644360110164e-005,999.890258789063,9.72367390990257e-005,999.890258789063,,,4.86756716656382e-008,5.45688649592953e-008,7.20200076269387e-007,,25,-0.00404106082394719,0.0100644360110164,0.0972367390990257,
,24068731.687,,1.99997613430023,-57971.6578125,0,-3.93239217810333e-006,999.890258789063,1.01005795225501e-005,999.890258789063,9.71159338951111e-005,999.890258789063,,,7.11189343075379e-008,5.89922711362114e-008,8.4322537512832e-007,,25,-0.00393239217810333,0.0101005795225501,0.0971159338951111,
,24068750.813,,2.00000113487244,-56478.884375,0,-3.74786078929901e-006,999.890258789063,1.00844075530767e-005,999.890258789063,9.71710729598999e-005,999.890258789063,,,5.25192346448802e-008,4.71215558773558e-008,7.66379965569307e-007,,25,-0.00374786078929901,0.0100844075530767,0.0971710729598999,
,24068769.299,,1.99999460220337,-55009.766875,0,-3.65669436752796e-006,999.890258789063,1.01226306706667e-005,999.890258789063,9.71231365203857e-005,999.890258789063,,,3.79647922279882e-008,4.92298296863199e-008,7.44346422029095e-007,,25,-0.00365669436752796,0.0101226306706667,0.0971231365203857,
,24068787.801,,2.0000138092041,-53515.225,0,-3.75827042385936e-006,999.890258789063,1.01431545242667e-005,999.890258789063,9.71117135882378e-005,999.890258789063,,,6.31043802698141e-008,5.60259313401806e-008,7.26218806109663e-007,,25,-0.00375827042385936,0.0101431545242667,0.0971117135882378,
,24068807.005,,1.999949426651,-52024.354375,0,-3.86960310861468e-006,999.890258789063,1.0171512067318e-005,999.890258789063,9.70004066824913e-005,999.890258789063,,,4.05471160967756e-008,5.0825998761238e-008,7.45789139959438e-007,,25,-0.00386960310861468,0.010171512067318,0.0970004066824913,
,24068825.444,,1.9999868106842,-50557.00046875,0,-3.8129916973412e-006,999.890258789063,1.015729367733e-005,999.890258789063,9.68781888484955e-005,999.890258789063,,,5.08596294120819e-008,4.84975378042859e-008,7.90342182654434e-007,,25,-0.0038129916973412,0.01015729367733,0.0968781888484955,
,24068844.086,,1.99995970249176,-49012.21625,0,-3.6577601544559e-006,999.890258789063,1.02172303199768e-005,999.890258789063,9.70771107077598e-005,999.890258789063,,,5.74111516697059e-008,5.09338178517596e-008,5.5961436187797e-007,,25,-0.0036577601544559,0.0102172303199768,0.0970771107077599,
,24068864.085,,1.99999757766724,-47475.7715625,0,-3.59314745292068e-006,999.890258789063,1.02279408276081e-005,999.890258789063,9.66699197888375e-005,999.890258789063,,,3.51508350722933e-008,6.33778079802055e-008,7.40772676612848e-007,,25,-0.00359314745292068,0.0102279408276081,0.0966699197888374,
,24068882.525,,1.9999666261673,-46003.995625,0,-3.66561409085989e-006,999.890258789063,1.02271880581975e-005,999.890258789063,9.67210459709168e-005,999.890258789063,,,3.5080500365656e-008,4.0638213877612e-008,6.91264387532507e-007,,25,-0.00366561409085989,0.0102271880581975,0.0967210459709167,
,24068900.995,,1.99993506908417,-44530.44484375,0,-3.62683601677418e-006,999.890258789063,1.02556848526001e-005,999.890258789063,9.66255909204483e-005,999.890258789063,,,5.16253515125753e-008,4.81583679023481e-008,7.73313729167473e-007,,25,-0.00362683601677418,0.0102556848526001,0.0966255909204483,
,24068919.684,,2.00002316474915,-43014.698125,0,-3.5378044936806e-006,999.890258789063,1.02792385593057e-005,999.890258789063,9.65887227654457e-005,999.890258789063,,,4.22267885478899e-008,4.5725123059721e-008,5.78562743998286e-007,,25,-0.0035378044936806,0.0102792385593057,0.0965887227654457,
,24068938.919,,1.99998198986053,-41520.7015625,0,-3.57508350163698e-006,999.890258789063,1.03041284531355e-005,999.890258789063,9.70033085346222e-005,999.890258789063,,,4.76632737202678e-008,4.46825508723593e-008,6.53990103345102e-007,,25,-0.00357508350163698,0.0103041284531355,0.0970033085346222,
,24068957.202,,1.99996486663818,-40038.57234375,0,-3.57111663557589e-006,999.890258789063,1.03164233267307e-005,999.890258789063,9.66530185937881e-005,999.890258789063,,,4.93696824488641e-008,3.74623940397405e-008,6.21034541366472e-007,,25,-0.00357111663557589,0.0103164233267307,0.0966530185937882,
,24068976.234,,1.99999024391174,-38497.63375,0,-3.47449589520693e-006,999.890258789063,1.03573852777481e-005,999.890258789063,9.65925258398056e-005,999.890258789063,,,4.54593277387068e-008,5.15998037129936e-008,6.10689082583737e-007,,25,-0.00347449589520693,0.0103573852777481,0.0965925258398056,
,24068995.766,,1.99991872787476,-36970.72890625,0,-3.46188963390887e-006,999.890258789063,1.03703115880489e-005,999.890258789063,9.62860292196274e-005,999.890258789063,,,4.64283490022649e-008,4.28925948773559e-008,7.26798277492331e-007,,25,-0.00346188963390887,0.0103703115880489,0.0962860292196274,
,24069014.33,,2.00001461029053,-35498.80671875,0,-3.37334040552378e-006,999.890258789063,1.03875412046909e-005,999.890258789063,9.626798838377e-005,999.890258789063,,,4.69296312405547e-008,4.39263870416393e-008,6.98691570580862e-007,,25,-0.00337334040552378,0.0103875412046909,0.09626798838377,
,24069033.05,,2.00000802993774,-33982.73515625,0,-3.37221790105104e-006,999.890258789063,1.03838791325688e-005,999.890258789063,9.62815442681313e-005,999.890258789063,,,4.38323340298689e-008,3.97534247548216e-008,6.54309460485127e-007,,25,-0.00337221790105104,0.0103838791325688,0.0962815442681313,
,24069052.238,,1.99991485595703,-32475.22328125,0,-3.37062988430262e-006,999.890258789063,1.04201318696141e-005,999.890258789063,9.65837162733078e-005,999.890258789063,,,3.62187278380992e-008,4.91764506624405e-008,4.98104935835331e-007,,25,-0.00337062988430262,0.0104201318696141,0.0965837162733078,
,24069070.755,,1.99993542671204,-30997.12609375,0,-3.37789435870946e-006,999.890258789063,1.04294754192233e-005,999.890258789063,9.65633210539818e-005,999.890258789063,,,3.34302903525135e-008,3.23793553007044e-008,5.04744236335127e-007,,25,-0.00337789435870945,0.0104294754192233,0.0965633210539818,
,24069090.412,,1.99997754573822,-29425.113203125,0,-3.31973725929856e-006,999.890258789063,1.04478233680129e-005,999.890258789063,9.6318579018116e-005,999.890258789063,,,3.19892808069511e-008,4.60859737456743e-008,7.057640736923e-007,,25,-0.00331973725929856,0.0104478233680129,0.096318579018116,
,24069109.6,,1.99993615150452,-27907.528515625,0,-3.28996781259775e-006,999.890258789063,1.04565406963229e-005,999.890258789063,9.63979819417e-005,999.890258789063,,,3.77090628593317e-008,3.3842556817596e-008,5.02233435737919e-007,,25,-0.00328996781259775,0.0104565406963229,0.0963979819417,
,24069128.304,,1.99995450973511,-26415.73578125,0,-3.27050419524312e-006,999.890258789063,1.04924813657999e-005,999.890258789063,9.62622728943825e-005,999.890258789063,,,3.84739930779096e-008,4.32857331762214e-008,5.18310938881084e-007,,25,-0.00327050419524312,0.0104924813657999,0.0962622728943825,
,24069146.697,,1.99996644020081,-24944.660390625,0,-3.21176650933921e-006,999.890258789063,1.0492791980505e-005,999.890258789063,9.63045334815979e-005,999.890258789063,,,4.42240949082236e-008,3.65955250251972e-008,6.47664670842074e-007,,25,-0.00321176650933921,0.010492791980505,0.0963045334815979,
,24069165.682,,2.00002359867096,-23403.702421875,0,-3.17370826378465e-006,999.890258789063,1.04993188381195e-005,999.890258789063,9.61876720190048e-005,999.890258789063,,,3.46408227555678e-008,2.7506092886289e-008,6.90413311017444e-007,,25,-0.00317370826378465,0.0104993188381195,0.0961876720190048,
,24069184.558,,1.99996343612671,-21919.9428125,0,-3.13296499662101e-006,999.890258789063,1.05083863064647e-005,999.890258789063,9.58464050292969e-005,999.890258789063,,,3.73371473772426e-008,2.35937951340633e-008,6.28956781083174e-007,,25,-0.00313296499662101,0.0105083863064647,0.0958464050292969,
,24069203.029,,1.99997152805328,-20445.51171875,0,-3.06968754157424e-006,999.890258789063,1.05047659575939e-005,999.890258789063,9.6017456650734e-005,999.890258789063,,,3.46742625357627e-008,2.97556008422424e-008,4.83385615280329e-007,,25,-0.00306968754157424,0.0105047659575939,0.096017456650734,
,24069221.421,,1.99996718883514,-18939.196875,0,-2.99527926370502e-006,999.890258789063,1.05100229009986e-005,999.890258789063,9.62073129415512e-005,999.890258789063,,,3.85198938921711e-008,2.98774017992614e-008,5.40342246849572e-007,,25,-0.00299527926370502,0.0105100229009986,0.0962073129415512,
,24069240.718,,1.99994349956512,-17416.250546875,0,-2.94298503547907e-006,999.890258789063,1.05184112116694e-005,999.890258789063,9.6104342341423e-005,999.890258789063,,,3.5733851043328e-008,3.46631056619994e-008,3.3404507616323e-007,,25,-0.00294298503547907,0.0105184112116694,0.096104342341423,
,24069260.343,,1.99996215343475,-15838.628671875,0,-2.86024341359735e-006,999.890258789063,1.05285431817174e-005,999.890258789063,9.61275941133499e-005,999.890258789063,,,2.76945581920376e-008,2.58361020141399e-008,3.66572319551707e-007,,25,-0.00286024341359735,0.0105285431817174,0.0961275941133499,
,24069279.282,,1.99989880561829,-14331.0939453125,0,-2.82459405250847e-006,999.890258789063,1.05275714769959e-005,999.890258789063,9.60937902331352e-005,999.890258789063,,,3.28377373961032e-008,2.38336774595613e-008,3.63674807263479e-007,,25,-0.00282459405250847,0.0105275714769959,0.0960937902331352,
,24069298.595,,1.99996754169464,-12758.180546875,0,-2.74718979373574e-006,999.890258789063,1.05190482363105e-005,999.890258789063,9.60966637730598e-005,999.890258789063,,,4.51165748568911e-008,2.32174491140466e-008,3.27769750939812e-007,,25,-0.00274718979373574,0.0105190482363105,0.0960966637730599,
,24069317.799,,2.00000376701355,-11271.7906640625,0,-2.66993172466755e-006,999.890258789063,1.05155952274799e-005,999.890258789063,9.58269432187081e-005,999.890258789063,,,4.62310997542625e-008,2.34095225977004e-008,4.19253573422343e-007,,25,-0.00266993172466755,0.0105155952274799,0.095826943218708,
,24069336.441,,2.00000495910645,-9771.7895703125,0,-2.60193588212132e-006,999.890258789063,1.05148307606578e-005,999.890258789063,9.61068385839463e-005,999.890258789063,,,3.66508159681488e-008,1.7926363378881e-008,2.08021479407788e-007,,25,-0.00260193588212132,0.0105148307606578,0.0961068385839462,
,24069355.91,,2.00007184028626,-8226.20173828125,0,-2.52208895049989e-006,999.890258789063,1.05006331577897e-005,999.890258789063,9.59580338001251e-005,999.890258789063,,,4.69489451533234e-008,2.38292550603332e-008,2.69478575161206e-007,,25,-0.00252208895049989,0.0105006331577897,0.0959580338001251,
,24069374.365,,2.0000053024292,-6748.3578125,0,-2.45280024595559e-006,999.890258789063,1.04938584566116e-005,999.890258789063,9.59604588150978e-005,999.890258789063,,,3.01852101628852e-008,1.23034688841466e-008,3.46765678085173e-007,,25,-0.00245280024595559,0.0104938584566116,0.0959604588150978,
,24069393.194,,2.00002574443817,-5250.7053125,0,-2.38474203273654e-006,999.890258789063,1.0489497333765e-005,999.890258789063,9.59546640515327e-005,999.890258789063,,,3.4224232141359e-008,1.58954120203524e-008,2.6591707985024e-007,,25,-0.00238474203273654,0.010489497333765,0.0959546640515327,
,24069411.992,,2.00004207611084,-3707.24100585938,0,-2.30840110220015e-006,999.890258789063,1.04787641391158e-005,999.890258789063,9.59227460622787e-005,999.890258789063,,,3.54518626269736e-008,1.58540285385304e-008,2.50724041713828e-007,,25,-0.00230840110220015,0.0104787641391158,0.0959227460622787,
,24069431.102,,2.00003975868225,-2204.94822753906,0,-2.24237442947924e-006,999.890258789063,1.04690315201879e-005,999.890258789063,9.59152102470398e-005,999.890258789063,,,2.85264747488504e-008,2.46336988635399e-008,2.54908669842955e-007,,25,-0.00224237442947924,0.0104690315201879,0.0959152102470398,
,24069449.713,,2.00028208732605,-726.413544464111,0,-2.18639629893005e-006,999.890258789063,1.04608947038651e-005,999.890258789063,9.59310758113861e-005,999.890258789063,,,3.64075295427107e-008,1.6320033982351e-008,2.48365080659624e-007,,25,-0.00218639629893005,0.0104608947038651,0.0959310758113861,
,24069468.667,,1.99940578460693,820.0964453125,0,-2.2015602979809e-006,999.890258789063,1.04687665402889e-005,999.890258789063,9.59683033823967e-005,999.890258789063,,,2.47036691603538e-008,2.07184461233242e-008,4.24265205026219e-007,,25,-0.0022015602979809,0.0104687665402889,0.0959683033823967,
,24069487.871,,2.00004951000214,2334.48921875,0,-2.29473751038313e-006,999.890258789063,1.0449410378933e-005,999.890258789063,9.59122937917709e-005,999.890258789063,,,1.01991715328712e-007,1.3755584941442e-007,3.3550048506862e-007,,25,-0.00229473751038313,0.010449410378933,0.0959122937917709,
,24069506.591,,1.99996029376984,3832.87248046875,0,-2.37046483904123e-006,999.890258789063,1.04964623227715e-005,999.890258789063,9.59281858801842e-005,999.890258789063,,,4.22388979812513e-008,1.71678699049003e-008,3.44627070393552e-007,,25,-0.00237046483904123,0.0104964623227715,0.0959281858801842,
,24069525.264,,1.9999282169342,5363.71279296875,0,-2.45859293267131e-006,999.890258789063,1.05037516728044e-005,999.890258789063,9.59453335404396e-005,999.890258789063,,,3.7646645058877e-008,1.77909164583086e-008,3.43946562004184e-007,,25,-0.00245859293267131,0.0105037516728044,0.0959453335404396,
,24069544.983,,2.00013738155365,6897.302265625,0,-2.55162538029254e-006,999.890258789063,1.05776375159621e-005,999.890258789063,9.59244024753571e-005,999.890258789063,,,3.43617552619799e-008,2.89945499320197e-007,2.17432974088904e-007,,25,-0.00255162538029253,0.0105776375159621,0.0959244024753571,
,24069563.734,,1.99985709667206,8392.990546875,0,-2.65201520174742e-006,999.890258789063,1.05296410620213e-005,999.890258789063,9.60508379340172e-005,999.890258789063,,,3.50208799513632e-008,1.61833923644566e-008,3.6796952067078e-007,,25,-0.00265201520174742,0.0105296410620213,0.0960508379340172,
,24069582.205,,1.99998857975006,9877.2877734375,0,-2.75198738090694e-006,999.890258789063,1.05386741086841e-005,999.890258789063,9.59921252727508e-005,999.890258789063,,,3.68004686441629e-008,1.73977546449479e-008,3.94758734098894e-007,,25,-0.00275198738090694,0.0105386741086841,0.0959921252727509,
,24069600.925,,2.0000243473053,11406.365234375,0,-2.87175863049924e-006,999.890258789063,1.05529070645571e-005,999.890258789063,9.60957589745521e-005,999.890258789063,,,5.71269535367854e-008,1.89217603643399e-008,3.27437541306713e-007,,25,-0.00287175863049924,0.0105529070645571,0.0960957589745522,
,24069620.316,,1.99999363899231,12922.145078125,0,-2.96514678746462e-006,999.890258789063,1.05582928657532e-005,999.890258789063,9.60824108123779e-005,999.890258789063,,,5.00002688486842e-008,1.98880336812832e-008,4.73510410430751e-007,,25,-0.00296514678746462,0.0105582928657532,0.0960824108123779,
,24069638.771,,1.99997509002686,14400.076875,0,-3.04277510382235e-006,999.890258789063,1.05677081272006e-005,999.890258789063,9.59968253970146e-005,999.890258789063,,,3.60196319041007e-008,2.5012803974981e-008,6.17385282742106e-007,,25,-0.00304277510382235,0.0105677081272006,0.0959968253970146,
,24069657.241,,2.00007225513458,15897.7644140625,0,-3.13800690695644e-006,999.890258789063,1.05720460414886e-005,999.890258789063,9.61158126592636e-005,999.890258789063,,,4.19414350762716e-008,2.44337911743077e-008,3.6173759570231e-007,,25,-0.00313800690695643,0.0105720460414886,0.0961158126592636,
,24069676.445,,2.00005950450897,17423.532421875,0,-3.20726962760091e-006,999.890258789063,1.05702112242579e-005,999.890258789063,9.61717867851258e-005,999.890258789063,,,3.38119816211812e-008,3.26534444530425e-008,5.08507796272168e-007,,25,-0.00320726962760091,0.0105702112242579,0.0961717867851257,
,24069695.009,,2.00002646446228,18904.166875,0,-3.31978429108858e-006,999.890258789063,1.05873928964138e-005,999.890258789063,9.60406294465065e-005,999.890258789063,,,2.97161693330234e-008,2.26884576825503e-008,4.89713951078277e-007,,25,-0.00331978429108858,0.0105873928964138,0.0960406294465065,
,24069713.495,,2.00003947257996,20408.9171875,0,-3.40966417454183e-006,999.890258789063,1.05777303501964e-005,999.890258789063,9.61626788973808e-005,999.890258789063,,,3.16960475648945e-008,2.72034376470437e-008,6.62789024522916e-007,,25,-0.00340966417454183,0.0105777303501964,0.0961626788973808,
,24069732.792,,2.00001403331757,21939.42125,0,-3.50075013004243e-006,999.890258789063,1.05704407021403e-005,999.890258789063,9.61821562051773e-005,999.890258789063,,,4.07833634813584e-008,3.27679544224335e-008,6.21472912171747e-007,,25,-0.00350075013004243,0.0105704407021403,0.0961821562051773,
,24069751.622,,2.00002081871033,23441.843046875,0,-3.59118628315628e-006,999.890258789063,1.05528053641319e-005,999.890258789063,9.6169311106205e-005,999.890258789063,,,3.34102658913701e-008,3.53497217686828e-008,6.7563538072574e-007,,25,-0.00359118628315628,0.0105528053641319,0.096169311106205,
,24069770.435,,2.00002468109131,24952.119296875,0,-3.68106942623854e-006,999.890258789063,1.05636855214834e-005,999.890258789063,9.60951367020607e-005,999.890258789063,,,4.40475233637282e-008,3.40870446813268e-008,6.71167010203476e-007,,25,-0.00368106942623854,0.0105636855214834,0.0960951367020607,
,24069789.592,,2.00008932590485,26476.388046875,0,-3.75886341556907e-006,999.890258789063,1.05477831885219e-005,999.890258789063,9.61987480521202e-005,999.890258789063,,,2.60966181805336e-008,2.72644593114512e-008,7.42449609923087e-007,,25,-0.00375886341556907,0.0105477831885219,0.0961987480521202,
,24069807.891,,2.00004674911499,27954.585625,0,-3.79433792084456e-006,999.890258789063,1.05355121567845e-005,999.890258789063,9.60062390565872e-005,999.890258789063,,,2.73120095511383e-008,3.42850037452905e-008,7.92684042693082e-007,,25,-0.00379433792084455,0.0105355121567845,0.0960062390565872,
,24069826.611,,2.00003583908081,29454.6546875,0,-3.84020985104144e-006,999.890258789063,1.05288212001324e-005,999.890258789063,9.62521928548812e-005,999.890258789063,,,4.02920503559712e-008,3.23823788632072e-008,8.09525397536629e-007,,25,-0.00384020985104144,0.0105288212001324,0.0962521928548813,
,24069845.285,,2.00002534389496,30980.25015625,0,-3.91652951948345e-006,999.890258789063,1.05105112865567e-005,999.890258789063,9.6357142329216e-005,999.890258789063,,,3.01432821852306e-008,4.41081863854772e-008,8.82941344165225e-007,,25,-0.00391652951948345,0.0105105112865567,0.096357142329216,
,24069864.582,,2.00002323627472,32482.503828125,0,-3.92970856279135e-006,999.890258789063,1.05167677626014e-005,999.890258789063,9.60715368390083e-005,999.890258789063,,,2.1872036400937e-008,4.59371489902876e-008,7.50859918786743e-007,,25,-0.00392970856279135,0.0105167677626014,0.0960715368390083,
,24069883.24,,2.0000094127655,33976.52765625,0,-3.97205351851881e-006,999.890258789063,1.04968500509858e-005,999.890258789063,9.63236224651337e-005,999.890258789063,,,2.88524021035702e-008,3.94218486106446e-008,9.92324828502695e-007,,25,-0.00397205351851881,0.0104968500509858,0.0963236224651337,
,24069901.554,,2.00003829956055,35507.06703125,0,-3.99371007457376e-006,999.890258789063,1.04768350347877e-005,999.890258789063,9.62889623641968e-005,999.890258789063,,,2.96988680729901e-008,2.90453495426172e-008,6.94536217498704e-007,,25,-0.00399371007457376,0.0104768350347877,0.0962889623641968,
,24069921.288,,2.00001536369324,37077.2409375,0,-4.12638440728188e-006,999.890258789063,1.04778258875012e-005,999.890258789063,9.64014983177185e-005,999.890258789063,,,4.33493873871306e-008,4.16905258517895e-008,9.47132003873578e-007,,25,-0.00412638440728188,0.0104778258875012,0.0964014983177185,
,24069940.367,,2.00005303382874,38560.28203125,0,-4.15803495794535e-006,999.890258789063,1.0442710109055e-005,999.890258789063,9.63995385169983e-005,999.890258789063,,,3.65205021438636e-008,4.01613332265041e-008,8.92166644446911e-007,,25,-0.00415803495794535,0.010442710109055,0.0963995385169983,
,24069958.838,,2.00003724098206,40058.01953125,0,-4.3190909922123e-006,999.890258789063,1.04454686492682e-005,999.890258789063,9.63035124540329e-005,999.890258789063,,,5.4061681940749e-008,5.75958446539993e-008,7.13790936098022e-007,,25,-0.0043190909922123,0.0104454686492682,0.0963035124540329,
,24069978.291,,2.00001037120819,41592.49796875,0,-4.35052711516619e-006,999.890258789063,1.04249569773674e-005,999.890258789063,9.65983515977859e-005,999.890258789063,,,2.81005015215467e-008,5.1763999007971e-008,9.73372089052426e-007,,25,-0.00435052711516619,0.0104249569773674,0.0965983515977859,
,24069996.777,,2.00003237724304,43087.85109375,0,-4.34510260820389e-006,999.890258789063,1.04008931666613e-005,999.890258789063,9.67046430706978e-005,999.890258789063,,,3.08299906046714e-008,4.58185229986217e-008,7.18713999886569e-007,,25,-0.00434510260820389,0.0104008931666613,0.0967046430706978,
,24070015.451,,2.00000182628632,44574.605625,0,-4.46130046620965e-006,999.890258789063,1.03927684947848e-005,999.890258789063,9.67058610916138e-005,999.890258789063,,,4.8214481823932e-008,4.50146183509554e-008,9.17309585535276e-007,,25,-0.00446130046620965,0.0103927684947848,0.0967058610916138,
,24070034.108,,2.00001691818237,46082.35859375,0,-4.52353889122605e-006,999.890258789063,1.03724370896816e-005,999.890258789063,9.65658780932427e-005,999.890258789063,,,3.3643791539445e-008,4.42675399556661e-008,1.00543916499052e-006,,25,-0.00452353889122605,0.0103724370896816,0.0965658780932426,
,24070052.641,,2.00001567840576,47562.1121875,0,-4.48686920106411e-006,999.890258789063,1.03528297692537e-005,999.890258789063,9.67110928893089e-005,999.890258789063,,,2.6870270656712e-008,5.57312286813764e-008,9.43258789288522e-007,,25,-0.00448686920106411,0.0103528297692537,0.0967110928893089,
,24070071.112,,2.00006746768951,49045.32609375,0,-4.5471609570086e-006,999.890258789063,1.03419806808233e-005,999.890258789063,9.65401721000671e-005,999.890258789063,,,6.16351876335567e-008,4.19324514539435e-008,8.63718040462977e-007,,25,-0.0045471609570086,0.0103419806808233,0.0965401721000671,
,24070089.941,,2.00005740642548,50578.04453125,0,-4.72917381674051e-006,999.890258789063,1.02912061288953e-005,999.890258789063,9.68778476119042e-005,999.890258789063,,,6.65439222865839e-008,3.99058008053806e-008,1.04605724073053e-006,,25,-0.00472917381674051,0.0102912061288953,0.0968778476119041,
,24070108.973,,2.00002491474152,52072.85765625,0,-4.82945626601577e-006,999.890258789063,1.03003787621856e-005,999.890258789063,9.68488758802414e-005,999.890258789063,,,2.797071491561e-008,4.65257971181278e-008,1.18140761661727e-006,,25,-0.00482945626601577,0.0103003787621856,0.0968488758802414,
,24070127.428,,2.00000960350037,53551.81765625,0,-4.72876755520702e-006,999.890258789063,1.02863513678312e-005,999.890258789063,9.65096428990364e-005,999.890258789063,,,5.55359276028502e-008,4.40447950002351e-008,9.6501323567223e-007,,25,-0.00472876755520701,0.0102863513678312,0.0965096428990364,
,24070145.992,,2.00006781578064,55056.15296875,0,-4.61676275357604e-006,999.890258789063,1.0265131033957e-005,999.890258789063,9.67746275663376e-005,999.890258789063,,,3.4480361052488e-008,4.88119900368491e-008,9.3047424642804e-007,,25,-0.00461676275357604,0.010265131033957,0.0967746275663376,
,24070165.087,,1.99998329162598,56567.5690625,0,-4.714146964252e-006,999.890258789063,1.02516517415643e-005,999.890258789063,9.64185774326325e-005,999.890258789063,,,6.95266764200816e-008,5.3275251398523e-008,6.83267310341353e-007,,25,-0.00471414696425199,0.0102516517415643,0.0964185774326324,
,24070183.604,,2.00001328468323,58045.73375,0,-4.96933836489916e-006,999.890258789063,1.02298942953348e-005,999.890258789063,9.68536829948425e-005,999.890258789063,,,9.67453364912723e-008,3.18870676270914e-008,8.8754615925448e-007,,25,-0.00496933836489916,0.0102298942953348,0.0968536829948425,
,24070201.997,,2.00002421855927,59528.2946875,0,-5.10616283863783e-006,999.890258789063,1.02189884334803e-005,999.890258789063,9.68050929903984e-005,999.890258789063,,,2.85159846243548e-008,5.81639262992851e-008,8.63548765882049e-007,,25,-0.00510616283863783,0.0102189884334803,0.0968050929903984,
,24070221.622,,1.99997562408447,61100.57625,0,-5.01183919608593e-006,999.890258789063,1.0199441164732e-005,999.890258789063,9.68888065218926e-005,999.890258789063,,,6.96337699641246e-008,4.48166866046336e-008,8.21775260164286e-007,,25,-0.00501183919608593,0.010199441164732,0.0968888065218926,
,24070240.201,,2.0000684595108,62579.605,0,-4.80053329840302e-006,999.890258789063,1.01700603216887e-005,999.890258789063,9.65617009997368e-005,999.890258789063,,,6.40000140477248e-008,5.82557861306513e-008,9.63956625696124e-007,,25,-0.00480053329840302,0.0101700603216887,0.0965617009997368,
,24070258.547,,2.00002403736115,64061.32265625,0,-4.6950532309711e-006,999.890258789063,1.01590797305107e-005,999.890258789063,9.73353591561318e-005,999.890258789063,,,2.64057845394346e-008,5.14060610963765e-008,4.93749880814028e-007,,25,-0.0046950532309711,0.0101590797305107,0.0973353591561317,
,24070277.47,,1.99999252796173,65587.1778125,0,-4.76659594103694e-006,999.890258789063,1.01359644159675e-005,999.890258789063,9.68482822179794e-005,999.890258789063,,,6.25094317757953e-008,6.23848008246384e-008,9.06642747911791e-007,,25,-0.00476659594103694,0.0101359644159675,0.0968482822179794,
,24070296.455,,1.99998763084412,67096.2803125,0,-4.97250096872449e-006,999.890258789063,1.01140720397234e-005,999.890258789063,9.72496172785759e-005,999.890258789063,,,7.76046700322542e-008,3.99853542063851e-008,8.47070266250353e-007,,25,-0.00497250096872449,0.0101140720397234,0.0972496172785759,
,24070314.926,,2.00007044792175,68570.795,0,-5.20311517640948e-006,999.890258789063,1.0100869089365e-005,999.890258789063,9.7039720416069e-005,999.890258789063,,,7.12131436082286e-008,5.29789336419504e-008,8.98009179119917e-007,,25,-0.00520311517640948,0.010100869089365,0.097039720416069,
,24070333.396,,1.99999480724335,70077.6021875,0,-5.3385840728879e-006,999.890258789063,1.00846641883254e-005,999.890258789063,9.68452587723732e-005,999.890258789063,,,2.54814991468701e-008,6.45891834366836e-008,8.8620896273117e-007,,25,-0.0053385840728879,0.0100846641883254,0.0968452587723732,
,24070352.662,,1.99999756813049,71586.8890625,0,-5.24667477235198e-006,999.890258789063,1.00778394564986e-005,999.890258789063,9.72954833507538e-005,999.890258789063,,,6.991883788785e-008,5.63339390567392e-008,9.92438977785477e-007,,25,-0.00524667477235198,0.0100778394564986,0.0972954833507538,
,24070371.164,,2.00001961231232,73062.5784375,0,-5.02902520820498e-006,999.890258789063,1.00492111593485e-005,999.890258789063,9.70501697063446e-005,999.890258789063,,,7.47583153577667e-008,4.92738138231376e-008,8.60797176045491e-007,,25,-0.00502902520820498,0.0100492111593485,0.0970501697063446,
,24070389.479,,1.99999423027039,74550.3484375,0,-4.8324635066092e-006,999.890258789063,1.00260701775551e-005,999.890258789063,9.72154340147972e-005,999.890258789063,,,6.18621239600904e-008,4.1326232650416e-008,1.38913699963289e-006,,25,-0.0048324635066092,0.0100260701775551,0.0972154340147972,
,24070408.651,,2.00001777172089,76077.3940625,0,-4.70988560467959e-006,999.890258789063,1.00465504452586e-005,999.890258789063,9.72635567188263e-005,999.890258789063,,,2.97825908838571e-008,4.80481870032047e-008,1.01247884000198e-006,,25,-0.00470988560467958,0.0100465504452586,0.0972635567188263,
,24070427.512,,1.99999384880066,77620.508125,0,-4.71728151664138e-006,999.890258789063,1.00105863809586e-005,999.890258789063,9.71980938315392e-005,999.890258789063,,,3.91651643348743e-008,6.39603937453104e-008,1.11237340250188e-006,,25,-0.00471728151664138,0.0100105863809586,0.0971980938315392,
,24070446.669,,2.0000227355957,79115.494375,0,-4.8743992857635e-006,999.890258789063,9.98488545417786e-006,999.890258789063,9.7270904481411e-005,999.890258789063,,,7.13336582502313e-008,7.16861798357712e-008,9.17964269305246e-007,,25,-0.0048743992857635,0.00998488545417786,0.097270904481411,
,24070465.404,,2.00008123397827,80663.2475,0,-5.16319258138537e-006,999.890258789063,1.00056369975209e-005,999.890258789063,9.73302945494652e-005,999.890258789063,,,9.51589047260346e-008,3.92184086868372e-008,6.76973972067326e-007,,25,-0.00516319258138537,0.0100056369975209,0.0973302945494652,
,24070484.483,,1.99997508049011,82148.4075,0,-5.51094612106681e-006,999.890258789063,1.00151610001922e-005,999.890258789063,9.73718905448914e-005,999.890258789063,,,9.77722934345791e-008,4.6597218302237e-008,7.89817727030675e-007,,25,-0.00551094612106681,0.0100151610001922,0.0973718905448914,
,24070503.266,,2.00000801563263,83648.3246875,0,-5.77323390170932e-006,999.890258789063,9.95297104120254e-006,999.890258789063,9.72471377253533e-005,999.890258789063,,,7.11943958835609e-008,5.96341504561379e-008,7.61335253715113e-007,,25,-0.00577323390170932,0.00995297104120254,0.0972471377253532,
,24070521.596,,1.99999822616577,85193.91375,0,-5.80943701788783e-006,999.890258789063,9.98863659799099e-006,999.890258789063,9.72695738077164e-005,999.890258789063,,,4.3269742293149e-008,7.29871530883519e-008,9.9336730192136e-007,,25,-0.00580943701788783,0.00998863659799099,0.0972695738077164,
,24070541.502,,2.00005474567413,86717.8965625,0,-5.6345028616488e-006,999.890258789063,9.93760488927364e-006,999.890258789063,9.70840194821358e-005,999.890258789063,,,8.30037997195157e-008,4.13673065992493e-008,7.58788324331256e-007,,25,-0.0056345028616488,0.00993760488927364,0.0970840194821358,
,24070560.003,,2.00000744342804,88198.370625,0,-5.33616732805967e-006,999.890258789063,9.94282640516758e-006,999.890258789063,9.73427343368531e-005,999.890258789063,,,8.57398553107824e-008,4.5543985838391e-008,8.71077867435972e-007,,25,-0.00533616732805967,0.00994282640516758,0.097342734336853,
,24070578.458,,1.99978420734406,89631.865625,0,-5.05622688680887e-006,999.890258789063,9.94234520941973e-006,999.890258789063,9.74225041270256e-005,999.890258789063,,,7.27802591225344e-008,9.91877402724663e-008,7.12015711694432e-007,,25,-0.00505622688680887,0.00994234520941973,0.0974225041270256,
,24070597.693,,1.99998500347137,90000.1375,0,-4.9971174262464e-006,999.890258789063,9.9286787956953e-006,999.890258789063,9.7260774075985e-005,999.890258789063,,,4.73911633827859e-008,7.00066164374897e-008,4.9526049249471e-007,,25,-0.00499711742624641,0.0099286787956953,0.0972607740759849,
,24070616.382,,2.00003479003906,90000.121875,0,-5.04737136885524e-006,999.890258789063,9.91281155496836e-006,999.890258789063,9.75646796822548e-005,999.890258789063,,,3.90007494766234e-007,8.65226856667532e-008,4.96333156235191e-007,,25,-0.00504737136885524,0.00991281155496836,0.0975646796822548,